<?xml version="1.0" encoding="utf-8"?>
<!-- =================================================================================== -->
<!-- |    This document was autogenerated by xacro from hithand_description/urdf/hithand.urdf.xacro | -->
<!-- |    EDITING THIS FILE BY HAND IS NOT RECOMMENDED                                 | -->
<!-- =================================================================================== -->
<robot name="hithand">
  <!-- END of hithand macro -->
  <transmission name="tran_Thumb_0">
    <type>transmission_interface/SimpleTransmission</type>
    <joint name="Right_Thumb_0">
      <hardwareInterface>hardware_interface/EffortJointInterface</hardwareInterface>
    </joint>
    <actuator name="motor_Thumb_0">
      <hardwareInterface>hardware_interface/EffortJointInterface</hardwareInterface>
      <mechanicalReduction>1</mechanicalReduction>
    </actuator>
  </transmission>
  <transmission name="tran_Thumb_1">
    <type>transmission_interface/SimpleTransmission</type>
    <joint name="Right_Thumb_1">
      <hardwareInterface>hardware_interface/EffortJointInterface</hardwareInterface>
    </joint>
    <actuator name="motor_Thumb_1">
      <hardwareInterface>hardware_interface/EffortJointInterface</hardwareInterface>
      <mechanicalReduction>1</mechanicalReduction>
    </actuator>
  </transmission>
  <transmission name="tran_Thumb_2">
    <type>transmission_interface/SimpleTransmission</type>
    <joint name="Right_Thumb_2">
      <hardwareInterface>hardware_interface/EffortJointInterface</hardwareInterface>
    </joint>
    <actuator name="motor_Thumb_2">
      <hardwareInterface>hardware_interface/EffortJointInterface</hardwareInterface>
      <mechanicalReduction>1</mechanicalReduction>
    </actuator>
  </transmission>
  <transmission name="tran_Thumb_3">
    <type>transmission_interface/SimpleTransmission</type>
    <joint name="Right_Thumb_3">
      <hardwareInterface>hardware_interface/EffortJointInterface</hardwareInterface>
    </joint>
    <actuator name="motor_Thumb_3">
      <hardwareInterface>hardware_interface/EffortJointInterface</hardwareInterface>
      <mechanicalReduction>1</mechanicalReduction>
    </actuator>
  </transmission>
  <transmission name="tran_Index_0">
    <type>transmission_interface/SimpleTransmission</type>
    <joint name="Right_Index_0">
      <hardwareInterface>hardware_interface/EffortJointInterface</hardwareInterface>
    </joint>
    <actuator name="motor_Index_0">
      <hardwareInterface>hardware_interface/EffortJointInterface</hardwareInterface>
      <mechanicalReduction>1</mechanicalReduction>
    </actuator>
  </transmission>
  <transmission name="tran_Index_1">
    <type>transmission_interface/SimpleTransmission</type>
    <joint name="Right_Index_1">
      <hardwareInterface>hardware_interface/EffortJointInterface</hardwareInterface>
    </joint>
    <actuator name="motor_Index_1">
      <hardwareInterface>hardware_interface/EffortJointInterface</hardwareInterface>
      <mechanicalReduction>1</mechanicalReduction>
    </actuator>
  </transmission>
  <transmission name="tran_Index_2">
    <type>transmission_interface/SimpleTransmission</type>
    <joint name="Right_Index_2">
      <hardwareInterface>hardware_interface/EffortJointInterface</hardwareInterface>
    </joint>
    <actuator name="motor_Index_2">
      <hardwareInterface>hardware_interface/EffortJointInterface</hardwareInterface>
      <mechanicalReduction>1</mechanicalReduction>
    </actuator>
  </transmission>
  <transmission name="tran_Index_3">
    <type>transmission_interface/SimpleTransmission</type>
    <joint name="Right_Index_3">
      <hardwareInterface>hardware_interface/EffortJointInterface</hardwareInterface>
    </joint>
    <actuator name="motor_Index_3">
      <hardwareInterface>hardware_interface/EffortJointInterface</hardwareInterface>
      <mechanicalReduction>1</mechanicalReduction>
    </actuator>
  </transmission>
  <transmission name="tran_Middle_0">
    <type>transmission_interface/SimpleTransmission</type>
    <joint name="Right_Middle_0">
      <hardwareInterface>hardware_interface/EffortJointInterface</hardwareInterface>
    </joint>
    <actuator name="motor_Middle_0">
      <hardwareInterface>hardware_interface/EffortJointInterface</hardwareInterface>
      <mechanicalReduction>1</mechanicalReduction>
    </actuator>
  </transmission>
  <transmission name="tran_Middle_1">
    <type>transmission_interface/SimpleTransmission</type>
    <joint name="Right_Middle_1">
      <hardwareInterface>hardware_interface/EffortJointInterface</hardwareInterface>
    </joint>
    <actuator name="motor_Middle_1">
      <hardwareInterface>hardware_interface/EffortJointInterface</hardwareInterface>
      <mechanicalReduction>1</mechanicalReduction>
    </actuator>
  </transmission>
  <transmission name="tran_Middle_2">
    <type>transmission_interface/SimpleTransmission</type>
    <joint name="Right_Middle_2">
      <hardwareInterface>hardware_interface/EffortJointInterface</hardwareInterface>
    </joint>
    <actuator name="motor_Middle_2">
      <hardwareInterface>hardware_interface/EffortJointInterface</hardwareInterface>
      <mechanicalReduction>1</mechanicalReduction>
    </actuator>
  </transmission>
  <transmission name="tran_Middle_3">
    <type>transmission_interface/SimpleTransmission</type>
    <joint name="Right_Middle_3">
      <hardwareInterface>hardware_interface/EffortJointInterface</hardwareInterface>
    </joint>
    <actuator name="motor_Middle_3">
      <hardwareInterface>hardware_interface/EffortJointInterface</hardwareInterface>
      <mechanicalReduction>1</mechanicalReduction>
    </actuator>
  </transmission>
  <transmission name="tran_Ring_0">
    <type>transmission_interface/SimpleTransmission</type>
    <joint name="Right_Ring_0">
      <hardwareInterface>hardware_interface/EffortJointInterface</hardwareInterface>
    </joint>
    <actuator name="motor_Ring_0">
      <hardwareInterface>hardware_interface/EffortJointInterface</hardwareInterface>
      <mechanicalReduction>1</mechanicalReduction>
    </actuator>
  </transmission>
  <transmission name="tran_Ring_1">
    <type>transmission_interface/SimpleTransmission</type>
    <joint name="Right_Ring_1">
      <hardwareInterface>hardware_interface/EffortJointInterface</hardwareInterface>
    </joint>
    <actuator name="motor_Ring_1">
      <hardwareInterface>hardware_interface/EffortJointInterface</hardwareInterface>
      <mechanicalReduction>1</mechanicalReduction>
    </actuator>
  </transmission>
  <transmission name="tran_Ring_2">
    <type>transmission_interface/SimpleTransmission</type>
    <joint name="Right_Ring_2">
      <hardwareInterface>hardware_interface/EffortJointInterface</hardwareInterface>
    </joint>
    <actuator name="motor_Ring_2">
      <hardwareInterface>hardware_interface/EffortJointInterface</hardwareInterface>
      <mechanicalReduction>1</mechanicalReduction>
    </actuator>
  </transmission>
  <transmission name="tran_Ring_3">
    <type>transmission_interface/SimpleTransmission</type>
    <joint name="Right_Ring_3">
      <hardwareInterface>hardware_interface/EffortJointInterface</hardwareInterface>
    </joint>
    <actuator name="motor_Ring_3">
      <hardwareInterface>hardware_interface/EffortJointInterface</hardwareInterface>
      <mechanicalReduction>1</mechanicalReduction>
    </actuator>
  </transmission>
  <transmission name="tran_Little_0">
    <type>transmission_interface/SimpleTransmission</type>
    <joint name="Right_Little_0">
      <hardwareInterface>hardware_interface/EffortJointInterface</hardwareInterface>
    </joint>
    <actuator name="motor_Little_0">
      <hardwareInterface>hardware_interface/EffortJointInterface</hardwareInterface>
      <mechanicalReduction>1</mechanicalReduction>
    </actuator>
  </transmission>
  <transmission name="tran_Little_1">
    <type>transmission_interface/SimpleTransmission</type>
    <joint name="Right_Little_1">
      <hardwareInterface>hardware_interface/EffortJointInterface</hardwareInterface>
    </joint>
    <actuator name="motor_Little_1">
      <hardwareInterface>hardware_interface/EffortJointInterface</hardwareInterface>
      <mechanicalReduction>1</mechanicalReduction>
    </actuator>
  </transmission>
  <transmission name="tran_Little_2">
    <type>transmission_interface/SimpleTransmission</type>
    <joint name="Right_Little_2">
      <hardwareInterface>hardware_interface/EffortJointInterface</hardwareInterface>
    </joint>
    <actuator name="motor_Little_2">
      <hardwareInterface>hardware_interface/EffortJointInterface</hardwareInterface>
      <mechanicalReduction>1</mechanicalReduction>
    </actuator>
  </transmission>
  <transmission name="tran_Little_3">
    <type>transmission_interface/SimpleTransmission</type>
    <joint name="Right_Little_3">
      <hardwareInterface>hardware_interface/EffortJointInterface</hardwareInterface>
    </joint>
    <actuator name="motor_Little_3">
      <hardwareInterface>hardware_interface/EffortJointInterface</hardwareInterface>
      <mechanicalReduction>1</mechanicalReduction>
    </actuator>
  </transmission>
  <!-- If the Hithand is attached to a robot, which also loads this ros_control shared library, the plugin should be deactived (commented out) here.
        If you spawn the Hithand standalone you need to uncomment this for the hithand_control to work.   -->
  <!-- <gazebo>
      <plugin name="gazebo_ros_control" filename="libgazebo_ros_control.so">
        <robotNamespace>/hithand</robotNamespace>
        <robotSimType>gazebo_ros_control/DefaultRobotHWSim</robotSimType>
      </plugin>
    </gazebo> -->
  <!-- Base link hithand -->
  <gazebo reference="base_link_hithand">
    <selfCollide>False</selfCollide>
    <static>False</static>
    <turnGravityOff>True</turnGravityOff>
    <mu1>0.8</mu1>
    <mu2>0.8</mu2>
  </gazebo>
  <!-- Thumb links -->
  <gazebo reference="Right_Thumb_Basecover">
    <selfCollide>False</selfCollide>
    <static>False</static>
    <turnGravityOff>True</turnGravityOff>
  </gazebo>
  <gazebo reference="Right_Thumb_Phaprox">
    <selfCollide>False</selfCollide>
    <static>False</static>
    <turnGravityOff>True</turnGravityOff>
    <mu1>0.8</mu1>
    <mu2>0.8</mu2>
  </gazebo>
  <gazebo reference="Right_Thumb_Phamed">
    <selfCollide>False</selfCollide>
    <static>False</static>
    <turnGravityOff>True</turnGravityOff>
    <mu1>0.6</mu1>
    <mu2>0.6</mu2>
  </gazebo>
  <gazebo reference="Right_Thumb_Phadist">
    <selfCollide>False</selfCollide>
    <static>False</static>
    <turnGravityOff>True</turnGravityOff>
    <mu1>0.8</mu1>
    <mu2>0.8</mu2>
  </gazebo>
  <!-- Index links -->
  <gazebo reference="Right_Index_Basecover">
    <selfCollide>False</selfCollide>
    <static>False</static>
    <turnGravityOff>True</turnGravityOff>
    <mu1>0.8</mu1>
    <mu2>0.8</mu2>
  </gazebo>
  <gazebo reference="Right_Index_Phaprox">
    <selfCollide>False</selfCollide>
    <static>False</static>
    <turnGravityOff>True</turnGravityOff>
    <mu1>0.8</mu1>
    <mu2>0.8</mu2>
  </gazebo>
  <gazebo reference="Right_Index_Phamed">
    <selfCollide>False</selfCollide>
    <static>False</static>
    <turnGravityOff>True</turnGravityOff>
    <mu1>0.6</mu1>
    <mu2>0.6</mu2>
  </gazebo>
  <gazebo reference="Right_Index_Phadist">
    <selfCollide>False</selfCollide>
    <static>False</static>
    <turnGravityOff>True</turnGravityOff>
    <mu1>0.8</mu1>
    <mu2>0.8</mu2>
  </gazebo>
  <!-- Middle links -->
  <gazebo reference="Right_Middle_Basecover">
    <selfCollide>False</selfCollide>
    <static>False</static>
    <turnGravityOff>True</turnGravityOff>
    <mu1>0.8</mu1>
    <mu2>0.8</mu2>
  </gazebo>
  <gazebo reference="Right_Middle_Phaprox">
    <selfCollide>False</selfCollide>
    <static>False</static>
    <turnGravityOff>True</turnGravityOff>
    <mu1>0.8</mu1>
    <mu2>0.8</mu2>
  </gazebo>
  <gazebo reference="Right_Middle_Phamed">
    <selfCollide>False</selfCollide>
    <static>False</static>
    <turnGravityOff>True</turnGravityOff>
    <mu1>0.6</mu1>
    <mu2>0.6</mu2>
  </gazebo>
  <gazebo reference="Right_Middle_Phadist">
    <selfCollide>False</selfCollide>
    <static>False</static>
    <turnGravityOff>True</turnGravityOff>
    <mu1>0.8</mu1>
    <mu2>0.8</mu2>
  </gazebo>
  <!-- Ring links -->
  <gazebo reference="Right_Ring_Basecover">
    <selfCollide>False</selfCollide>
    <static>False</static>
    <turnGravityOff>True</turnGravityOff>
    <mu1>0.8</mu1>
    <mu2>0.8</mu2>
  </gazebo>
  <gazebo reference="Right_Ring_Phaprox">
    <selfCollide>False</selfCollide>
    <static>False</static>
    <turnGravityOff>True</turnGravityOff>
    <mu1>0.8</mu1>
    <mu2>0.8</mu2>
  </gazebo>
  <gazebo reference="Right_Ring_Phamed">
    <selfCollide>False</selfCollide>
    <static>False</static>
    <turnGravityOff>True</turnGravityOff>
    <mu1>0.6</mu1>
    <mu2>0.6</mu2>
  </gazebo>
  <gazebo reference="Right_Ring_Phadist">
    <selfCollide>False</selfCollide>
    <static>False</static>
    <turnGravityOff>True</turnGravityOff>
    <mu1>0.8</mu1>
    <mu2>0.8</mu2>
  </gazebo>
  <!-- Little links -->
  <gazebo reference="Right_Little_Basecover">
    <selfCollide>False</selfCollide>
    <static>False</static>
    <turnGravityOff>True</turnGravityOff>
    <mu1>0.8</mu1>
    <mu2>0.8</mu2>
  </gazebo>
  <gazebo reference="Right_Little_Phaprox">
    <selfCollide>False</selfCollide>
    <static>False</static>
    <turnGravityOff>True</turnGravityOff>
    <mu1>0.8</mu1>
    <mu2>0.8</mu2>
  </gazebo>
  <gazebo reference="Right_Little_Phamed">
    <selfCollide>False</selfCollide>
    <static>False</static>
    <turnGravityOff>True</turnGravityOff>
    <mu1>0.6</mu1>
    <mu2>0.6</mu2>
  </gazebo>
  <gazebo reference="Right_Little_Phadist">
    <selfCollide>False</selfCollide>
    <static>False</static>
    <turnGravityOff>True</turnGravityOff>
    <mu1>0.8</mu1>
    <mu2>0.8</mu2>
  </gazebo>
  <link name="world"/>
  <joint name="fixed" type="fixed">
    <parent link="world"/>
    <child link="base_link_hithand"/>
    <origin rpy="0 0 0" xyz="0 0 0"/>
  </joint>
  <!-- ++++ Define all the links and joints ++++ -->
  <!-- Starting from the base -->
  <link name="base_link_hithand">
    <inertial>
      <origin rpy="0 0 0" xyz="0.0112 0.0 0.0566"/>
      <mass value="1.1485"/>
      <inertia ixx="2.2458e-3" ixy="-2.7421e-4" ixz="1.6e-5" iyy="2.2203e-3" iyz="-6.37e-5" izz="1.9003e-3"/>
    </inertial>
    <visual>
      <origin rpy="0 0 0" xyz="0 0 0"/>
      <geometry>
        <mesh filename="meshes/visual/palm/hit-hand-2-palm-right.dae"/>
      </geometry>
      <material name="grey"/>
    </visual>
    <collision>
      <origin rpy="0 0 0" xyz="0 0 0"/>
      <geometry>
        <mesh filename="meshes/collision/palm/hit-hand-2-palm-right-merged.dae"/>
      </geometry>
    </collision>
  </link>
  <!-- Add a virtual palm link to get the transform of this point via TF for grasping (we align this frame with
        a normal of a point from an object point cloud.) -->
  <joint name="hithand_palm_joint" type="fixed">
    <parent link="base_link_hithand"/>
    <child link="palm_link_hithand"/>
    <origin rpy="-0.15 -1.3 0" xyz="0.02 0 0.06"/>
  </joint>
  <link name="palm_link_hithand"/>
  <!-- #########################FINGER######################## -->
  <!-- END of finger macro -->
  <!-- +++++ Finger base joint 0 ++++++ -->
  <joint name="Right_Thumb_0" type="revolute">
    <!-- joint origin in parent link frame -->
    <origin rpy="0.225810 -1.083656 0.411355" xyz="0.06217593 0.044372912 0.078734808"/>
    <parent link="base_link_hithand"/>
    <child link="Right_Thumb_Basecover"/>
    <axis xyz="0 0 1"/>
    <limit effort="15" lower="-0.261799" upper="0.261799" velocity="3.14"/>
    <dynamics damping="0.5" friction="0"/>
  </joint>
  <link name="Right_Thumb_Basecover">
    <inertial>
      <origin rpy="0 0 0" xyz="0.02749 0 0"/>
      <mass value="0.0176"/>
      <inertia ixx="1.3450e-6" ixy="0.0" ixz="-1.8183e-7" iyy="1.9874e-6" iyz="0.0" izz="1.0419e-6"/>
    </inertial>
    <visual>
      <origin rpy="0 0 0" xyz="0 0 0"/>
      <geometry>
        <mesh filename="meshes/visual/finger/hit-hand-2-finger-basecover.dae"/>
      </geometry>
      <material name="white"/>
    </visual>
    <collision>
      <origin rpy="0 0 0" xyz="0 0 0"/>
      <geometry name="hithand_Thumb_base_cover">
        <cylinder length="0.001" radius="0.001"/>
      </geometry>
    </collision>
  </link>
  <!-- +++++ Finger joint 1, Link: Phalanx proximalis ++++++ -->
  <joint name="Right_Thumb_1" type="revolute">
    <origin rpy="1.5708 0 0" xyz="0 0 0 "/>
    <parent link="Right_Thumb_Basecover"/>
    <child link="Right_Thumb_Phaprox"/>
    <axis xyz="0 0 1"/>
    <limit effort="1.15" lower="0.0" upper="1.48353" velocity="3.14"/>
    <!-- Effort limit based on max fingertip force of 10N. Finger tip is approx 11.5cm away from this joint.-->
    <dynamics damping="0.5" friction="0"/>
  </joint>
  <link name="Right_Thumb_Phaprox">
    <inertial>
      <origin rpy="0 0 0" xyz="0.03076 0.00297 0"/>
      <mass value="0.0232"/>
      <inertia ixx="2.5326e-6" ixy="-9.2551e-7" ixz="-4.0954e-8" iyy="6.9625e-6" iyz="-9.38e-9" izz="7.9108e-6"/>
    </inertial>
    <visual>
      <origin rpy="0 0 0" xyz="0 0 0"/>
      <geometry>
        <mesh filename="meshes/visual/finger/hit-hand-2-finger-phaprox.dae"/>
      </geometry>
      <material name="lightblue"/>
    </visual>
    <collision>
      <origin rpy="0 0 0" xyz="0 0 0"/>
      <geometry>
        <mesh filename="meshes/collision/finger/hit-hand-2-finger-phaprox.dae"/>
      </geometry>
    </collision>
  </link>
  <!-- +++++ Finger joint 2 Phalanx medialis ++++++ -->
  <joint name="Right_Thumb_2" type="revolute">
    <origin rpy="0 0 0" xyz="0.055 0 0"/>
    <parent link="Right_Thumb_Phaprox"/>
    <child link="Right_Thumb_Phamed"/>
    <axis xyz="0 0 1"/>
    <limit effort="0.6" lower="0.0" upper="1.13446" velocity="3.14"/>
    <!-- Effort limit based on max fingertip force of 10N. Finger tip is approx 6cm away from this joint.-->
    <dynamics damping="0.5" friction="0"/>
  </joint>
  <link name="Right_Thumb_Phamed">
    <inertial>
      <origin rpy="0 0 0" xyz="0.0097 -0.00036 0"/>
      <mass value="0.0158"/>
      <inertia ixx="1.1852e-6" ixy="-2.8845e-8" ixz="-6.1323e-9" iyy="2.4460e-6" iyz="2.4541e-9" izz="2.6537e-6"/>
    </inertial>
    <visual>
      <origin rpy="0 0 0" xyz="0 0 0"/>
      <geometry>
        <mesh filename="meshes/visual/finger/hit-hand-2-finger-phamed.dae"/>
      </geometry>
      <material name="white"/>
    </visual>
    <collision>
      <origin rpy="0 0 0" xyz="0 0 0"/>
      <geometry>
        <mesh filename="meshes/collision/finger/hit-hand-2-finger-phamed.dae"/>
      </geometry>
    </collision>
  </link>
  <!-- +++++ Finger joint 3 Phalanx distalis ++++++ -->
  <joint name="Right_Thumb_3" type="revolute">
    <origin rpy="0 0 -1.570796" xyz="0.025 0 0"/>
    <parent link="Right_Thumb_Phamed"/>
    <child link="Right_Thumb_Phadist"/>
    <axis xyz="0 0 1"/>
    <limit effort="0.35" lower="0.0" upper="1.13446" velocity="3.14"/>
    <!-- Effort limit based on max fingertip force of 10N. Finger tip is approx 3.5cm away from this joint.-->
    <dynamics damping="0.5" friction="0"/>
  </joint>
  <link name="Right_Thumb_Phadist">
    <inertial>
      <origin rpy="0 0 0" xyz="0.00072 0.00717 0.0"/>
      <mass value="0.0137"/>
      <inertia ixx="1.5519e-6" ixy="-2.037e-9" ixz="0.0" iyy="8.2972e-7" iyz="3.77e-9" izz="1.5788e-6"/>
    </inertial>
    <visual>
      <origin rpy="0 0 0" xyz="0 0 0"/>
      <geometry>
        <mesh filename="meshes/visual/finger/hit-hand-2-finger-phadist.dae"/>
      </geometry>
      <material name="lightblue"/>
    </visual>
    <collision>
      <origin rpy="0 0 0" xyz="0 0 0"/>
      <geometry>
        <mesh filename="meshes/collision/finger/hit-hand-2-finger-phadist.dae"/>
      </geometry>
    </collision>
  </link>
  <!-- +++++ Finger base joint 0 ++++++ -->
  <joint name="Right_Index_0" type="revolute">
    <!-- joint origin in parent link frame -->
    <origin rpy="3.054326 -1.570796 0.000000" xyz="-0.002529881 0.03680013 0.107783545"/>
    <parent link="base_link_hithand"/>
    <child link="Right_Index_Basecover"/>
    <axis xyz="0 0 1"/>
    <limit effort="15" lower="-0.261799" upper="0.261799" velocity="3.14"/>
    <dynamics damping="0.5" friction="0"/>
  </joint>
  <link name="Right_Index_Basecover">
    <inertial>
      <origin rpy="0 0 0" xyz="0.02749 0 0"/>
      <mass value="0.0176"/>
      <inertia ixx="1.3450e-6" ixy="0.0" ixz="-1.8183e-7" iyy="1.9874e-6" iyz="0.0" izz="1.0419e-6"/>
    </inertial>
    <visual>
      <origin rpy="0 0 0" xyz="0 0 0"/>
      <geometry>
        <mesh filename="meshes/visual/finger/hit-hand-2-finger-basecover.dae"/>
      </geometry>
      <material name="white"/>
    </visual>
    <collision>
      <origin rpy="0 0 0" xyz="0 0 0"/>
      <geometry name="hithand_Index_base_cover">
        <cylinder length="0.001" radius="0.001"/>
      </geometry>
    </collision>
  </link>
  <!-- +++++ Finger joint 1, Link: Phalanx proximalis ++++++ -->
  <joint name="Right_Index_1" type="revolute">
    <origin rpy="1.5708 0 0" xyz="0 0 0 "/>
    <parent link="Right_Index_Basecover"/>
    <child link="Right_Index_Phaprox"/>
    <axis xyz="0 0 1"/>
    <limit effort="1.15" lower="0.0" upper="1.48353" velocity="3.14"/>
    <!-- Effort limit based on max fingertip force of 10N. Finger tip is approx 11.5cm away from this joint.-->
    <dynamics damping="0.5" friction="0"/>
  </joint>
  <link name="Right_Index_Phaprox">
    <inertial>
      <origin rpy="0 0 0" xyz="0.03076 0.00297 0"/>
      <mass value="0.0232"/>
      <inertia ixx="2.5326e-6" ixy="-9.2551e-7" ixz="-4.0954e-8" iyy="6.9625e-6" iyz="-9.38e-9" izz="7.9108e-6"/>
    </inertial>
    <visual>
      <origin rpy="0 0 0" xyz="0 0 0"/>
      <geometry>
        <mesh filename="meshes/visual/finger/hit-hand-2-finger-phaprox.dae"/>
      </geometry>
      <material name="lightblue"/>
    </visual>
    <collision>
      <origin rpy="0 0 0" xyz="0 0 0"/>
      <geometry>
        <mesh filename="meshes/collision/finger/hit-hand-2-finger-phaprox.dae"/>
      </geometry>
    </collision>
  </link>
  <!-- +++++ Finger joint 2 Phalanx medialis ++++++ -->
  <joint name="Right_Index_2" type="revolute">
    <origin rpy="0 0 0" xyz="0.055 0 0"/>
    <parent link="Right_Index_Phaprox"/>
    <child link="Right_Index_Phamed"/>
    <axis xyz="0 0 1"/>
    <limit effort="0.6" lower="0.0" upper="1.13446" velocity="3.14"/>
    <!-- Effort limit based on max fingertip force of 10N. Finger tip is approx 6cm away from this joint.-->
    <dynamics damping="0.5" friction="0"/>
  </joint>
  <link name="Right_Index_Phamed">
    <inertial>
      <origin rpy="0 0 0" xyz="0.0097 -0.00036 0"/>
      <mass value="0.0158"/>
      <inertia ixx="1.1852e-6" ixy="-2.8845e-8" ixz="-6.1323e-9" iyy="2.4460e-6" iyz="2.4541e-9" izz="2.6537e-6"/>
    </inertial>
    <visual>
      <origin rpy="0 0 0" xyz="0 0 0"/>
      <geometry>
        <mesh filename="meshes/visual/finger/hit-hand-2-finger-phamed.dae"/>
      </geometry>
      <material name="white"/>
    </visual>
    <collision>
      <origin rpy="0 0 0" xyz="0 0 0"/>
      <geometry>
        <mesh filename="meshes/collision/finger/hit-hand-2-finger-phamed.dae"/>
      </geometry>
    </collision>
  </link>
  <!-- +++++ Finger joint 3 Phalanx distalis ++++++ -->
  <joint name="Right_Index_3" type="revolute">
    <origin rpy="0 0 -1.570796" xyz="0.025 0 0"/>
    <parent link="Right_Index_Phamed"/>
    <child link="Right_Index_Phadist"/>
    <axis xyz="0 0 1"/>
    <limit effort="0.35" lower="0.0" upper="1.13446" velocity="3.14"/>
    <!-- Effort limit based on max fingertip force of 10N. Finger tip is approx 3.5cm away from this joint.-->
    <dynamics damping="0.5" friction="0"/>
  </joint>
  <link name="Right_Index_Phadist">
    <inertial>
      <origin rpy="0 0 0" xyz="0.00072 0.00717 0.0"/>
      <mass value="0.0137"/>
      <inertia ixx="1.5519e-6" ixy="-2.037e-9" ixz="0.0" iyy="8.2972e-7" iyz="3.77e-9" izz="1.5788e-6"/>
    </inertial>
    <visual>
      <origin rpy="0 0 0" xyz="0 0 0"/>
      <geometry>
        <mesh filename="meshes/visual/finger/hit-hand-2-finger-phadist.dae"/>
      </geometry>
      <material name="lightblue"/>
    </visual>
    <collision>
      <origin rpy="0 0 0" xyz="0 0 0"/>
      <geometry>
        <mesh filename="meshes/collision/finger/hit-hand-2-finger-phadist.dae"/>
      </geometry>
    </collision>
  </link>
  <!-- +++++ Finger base joint 0 ++++++ -->
  <joint name="Right_Middle_0" type="revolute">
    <!-- joint origin in parent link frame -->
    <origin rpy="-3.141593 -1.570796 0.000000" xyz="-0.0037 0.01  0.117783545"/>
    <parent link="base_link_hithand"/>
    <child link="Right_Middle_Basecover"/>
    <axis xyz="0 0 1"/>
    <limit effort="15" lower="-0.261799" upper="0.261799" velocity="3.14"/>
    <dynamics damping="0.5" friction="0"/>
  </joint>
  <link name="Right_Middle_Basecover">
    <inertial>
      <origin rpy="0 0 0" xyz="0.02749 0 0"/>
      <mass value="0.0176"/>
      <inertia ixx="1.3450e-6" ixy="0.0" ixz="-1.8183e-7" iyy="1.9874e-6" iyz="0.0" izz="1.0419e-6"/>
    </inertial>
    <visual>
      <origin rpy="0 0 0" xyz="0 0 0"/>
      <geometry>
        <mesh filename="meshes/visual/finger/hit-hand-2-finger-basecover.dae"/>
      </geometry>
      <material name="white"/>
    </visual>
    <collision>
      <origin rpy="0 0 0" xyz="0 0 0"/>
      <geometry name="hithand_Middle_base_cover">
        <cylinder length="0.001" radius="0.001"/>
      </geometry>
    </collision>
  </link>
  <!-- +++++ Finger joint 1, Link: Phalanx proximalis ++++++ -->
  <joint name="Right_Middle_1" type="revolute">
    <origin rpy="1.5708 0 0" xyz="0 0 0 "/>
    <parent link="Right_Middle_Basecover"/>
    <child link="Right_Middle_Phaprox"/>
    <axis xyz="0 0 1"/>
    <limit effort="1.15" lower="0.0" upper="1.48353" velocity="3.14"/>
    <!-- Effort limit based on max fingertip force of 10N. Finger tip is approx 11.5cm away from this joint.-->
    <dynamics damping="0.5" friction="0"/>
  </joint>
  <link name="Right_Middle_Phaprox">
    <inertial>
      <origin rpy="0 0 0" xyz="0.03076 0.00297 0"/>
      <mass value="0.0232"/>
      <inertia ixx="2.5326e-6" ixy="-9.2551e-7" ixz="-4.0954e-8" iyy="6.9625e-6" iyz="-9.38e-9" izz="7.9108e-6"/>
    </inertial>
    <visual>
      <origin rpy="0 0 0" xyz="0 0 0"/>
      <geometry>
        <mesh filename="meshes/visual/finger/hit-hand-2-finger-phaprox.dae"/>
      </geometry>
      <material name="lightblue"/>
    </visual>
    <collision>
      <origin rpy="0 0 0" xyz="0 0 0"/>
      <geometry>
        <mesh filename="meshes/collision/finger/hit-hand-2-finger-phaprox.dae"/>
      </geometry>
    </collision>
  </link>
  <!-- +++++ Finger joint 2 Phalanx medialis ++++++ -->
  <joint name="Right_Middle_2" type="revolute">
    <origin rpy="0 0 0" xyz="0.055 0 0"/>
    <parent link="Right_Middle_Phaprox"/>
    <child link="Right_Middle_Phamed"/>
    <axis xyz="0 0 1"/>
    <limit effort="0.6" lower="0.0" upper="1.13446" velocity="3.14"/>
    <!-- Effort limit based on max fingertip force of 10N. Finger tip is approx 6cm away from this joint.-->
    <dynamics damping="0.5" friction="0"/>
  </joint>
  <link name="Right_Middle_Phamed">
    <inertial>
      <origin rpy="0 0 0" xyz="0.0097 -0.00036 0"/>
      <mass value="0.0158"/>
      <inertia ixx="1.1852e-6" ixy="-2.8845e-8" ixz="-6.1323e-9" iyy="2.4460e-6" iyz="2.4541e-9" izz="2.6537e-6"/>
    </inertial>
    <visual>
      <origin rpy="0 0 0" xyz="0 0 0"/>
      <geometry>
        <mesh filename="meshes/visual/finger/hit-hand-2-finger-phamed.dae"/>
      </geometry>
      <material name="white"/>
    </visual>
    <collision>
      <origin rpy="0 0 0" xyz="0 0 0"/>
      <geometry>
        <mesh filename="meshes/collision/finger/hit-hand-2-finger-phamed.dae"/>
      </geometry>
    </collision>
  </link>
  <!-- +++++ Finger joint 3 Phalanx distalis ++++++ -->
  <joint name="Right_Middle_3" type="revolute">
    <origin rpy="0 0 -1.570796" xyz="0.025 0 0"/>
    <parent link="Right_Middle_Phamed"/>
    <child link="Right_Middle_Phadist"/>
    <axis xyz="0 0 1"/>
    <limit effort="0.35" lower="0.0" upper="1.13446" velocity="3.14"/>
    <!-- Effort limit based on max fingertip force of 10N. Finger tip is approx 3.5cm away from this joint.-->
    <dynamics damping="0.5" friction="0"/>
  </joint>
  <link name="Right_Middle_Phadist">
    <inertial>
      <origin rpy="0 0 0" xyz="0.00072 0.00717 0.0"/>
      <mass value="0.0137"/>
      <inertia ixx="1.5519e-6" ixy="-2.037e-9" ixz="0.0" iyy="8.2972e-7" iyz="3.77e-9" izz="1.5788e-6"/>
    </inertial>
    <visual>
      <origin rpy="0 0 0" xyz="0 0 0"/>
      <geometry>
        <mesh filename="meshes/visual/finger/hit-hand-2-finger-phadist.dae"/>
      </geometry>
      <material name="lightblue"/>
    </visual>
    <collision>
      <origin rpy="0 0 0" xyz="0 0 0"/>
      <geometry>
        <mesh filename="meshes/collision/finger/hit-hand-2-finger-phadist.dae"/>
      </geometry>
    </collision>
  </link>
  <!-- +++++ Finger base joint 0 ++++++ -->
  <joint name="Right_Ring_0" type="revolute">
    <!-- joint origin in parent link frame -->
    <origin rpy="-3.054326 -1.570796 0.000000" xyz="0 -0.01680013 0.11258354"/>
    <parent link="base_link_hithand"/>
    <child link="Right_Ring_Basecover"/>
    <axis xyz="0 0 1"/>
    <limit effort="15" lower="-0.261799" upper="0.261799" velocity="3.14"/>
    <dynamics damping="0.5" friction="0"/>
  </joint>
  <link name="Right_Ring_Basecover">
    <inertial>
      <origin rpy="0 0 0" xyz="0.02749 0 0"/>
      <mass value="0.0176"/>
      <inertia ixx="1.3450e-6" ixy="0.0" ixz="-1.8183e-7" iyy="1.9874e-6" iyz="0.0" izz="1.0419e-6"/>
    </inertial>
    <visual>
      <origin rpy="0 0 0" xyz="0 0 0"/>
      <geometry>
        <mesh filename="meshes/visual/finger/hit-hand-2-finger-basecover.dae"/>
      </geometry>
      <material name="white"/>
    </visual>
    <collision>
      <origin rpy="0 0 0" xyz="0 0 0"/>
      <geometry name="hithand_Ring_base_cover">
        <cylinder length="0.001" radius="0.001"/>
      </geometry>
    </collision>
  </link>
  <!-- +++++ Finger joint 1, Link: Phalanx proximalis ++++++ -->
  <joint name="Right_Ring_1" type="revolute">
    <origin rpy="1.5708 0 0" xyz="0 0 0 "/>
    <parent link="Right_Ring_Basecover"/>
    <child link="Right_Ring_Phaprox"/>
    <axis xyz="0 0 1"/>
    <limit effort="1.15" lower="0.0" upper="1.48353" velocity="3.14"/>
    <!-- Effort limit based on max fingertip force of 10N. Finger tip is approx 11.5cm away from this joint.-->
    <dynamics damping="0.5" friction="0"/>
  </joint>
  <link name="Right_Ring_Phaprox">
    <inertial>
      <origin rpy="0 0 0" xyz="0.03076 0.00297 0"/>
      <mass value="0.0232"/>
      <inertia ixx="2.5326e-6" ixy="-9.2551e-7" ixz="-4.0954e-8" iyy="6.9625e-6" iyz="-9.38e-9" izz="7.9108e-6"/>
    </inertial>
    <visual>
      <origin rpy="0 0 0" xyz="0 0 0"/>
      <geometry>
        <mesh filename="meshes/visual/finger/hit-hand-2-finger-phaprox.dae"/>
      </geometry>
      <material name="lightblue"/>
    </visual>
    <collision>
      <origin rpy="0 0 0" xyz="0 0 0"/>
      <geometry>
        <mesh filename="meshes/collision/finger/hit-hand-2-finger-phaprox.dae"/>
      </geometry>
    </collision>
  </link>
  <!-- +++++ Finger joint 2 Phalanx medialis ++++++ -->
  <joint name="Right_Ring_2" type="revolute">
    <origin rpy="0 0 0" xyz="0.055 0 0"/>
    <parent link="Right_Ring_Phaprox"/>
    <child link="Right_Ring_Phamed"/>
    <axis xyz="0 0 1"/>
    <limit effort="0.6" lower="0.0" upper="1.13446" velocity="3.14"/>
    <!-- Effort limit based on max fingertip force of 10N. Finger tip is approx 6cm away from this joint.-->
    <dynamics damping="0.5" friction="0"/>
  </joint>
  <link name="Right_Ring_Phamed">
    <inertial>
      <origin rpy="0 0 0" xyz="0.0097 -0.00036 0"/>
      <mass value="0.0158"/>
      <inertia ixx="1.1852e-6" ixy="-2.8845e-8" ixz="-6.1323e-9" iyy="2.4460e-6" iyz="2.4541e-9" izz="2.6537e-6"/>
    </inertial>
    <visual>
      <origin rpy="0 0 0" xyz="0 0 0"/>
      <geometry>
        <mesh filename="meshes/visual/finger/hit-hand-2-finger-phamed.dae"/>
      </geometry>
      <material name="white"/>
    </visual>
    <collision>
      <origin rpy="0 0 0" xyz="0 0 0"/>
      <geometry>
        <mesh filename="meshes/collision/finger/hit-hand-2-finger-phamed.dae"/>
      </geometry>
    </collision>
  </link>
  <!-- +++++ Finger joint 3 Phalanx distalis ++++++ -->
  <joint name="Right_Ring_3" type="revolute">
    <origin rpy="0 0 -1.570796" xyz="0.025 0 0"/>
    <parent link="Right_Ring_Phamed"/>
    <child link="Right_Ring_Phadist"/>
    <axis xyz="0 0 1"/>
    <limit effort="0.35" lower="0.0" upper="1.13446" velocity="3.14"/>
    <!-- Effort limit based on max fingertip force of 10N. Finger tip is approx 3.5cm away from this joint.-->
    <dynamics damping="0.5" friction="0"/>
  </joint>
  <link name="Right_Ring_Phadist">
    <inertial>
      <origin rpy="0 0 0" xyz="0.00072 0.00717 0.0"/>
      <mass value="0.0137"/>
      <inertia ixx="1.5519e-6" ixy="-2.037e-9" ixz="0.0" iyy="8.2972e-7" iyz="3.77e-9" izz="1.5788e-6"/>
    </inertial>
    <visual>
      <origin rpy="0 0 0" xyz="0 0 0"/>
      <geometry>
        <mesh filename="meshes/visual/finger/hit-hand-2-finger-phadist.dae"/>
      </geometry>
      <material name="lightblue"/>
    </visual>
    <collision>
      <origin rpy="0 0 0" xyz="0 0 0"/>
      <geometry>
        <mesh filename="meshes/collision/finger/hit-hand-2-finger-phadist.dae"/>
      </geometry>
    </collision>
  </link>
  <!-- +++++ Finger base joint 0 ++++++ -->
  <joint name="Right_Little_0" type="revolute">
    <!-- joint origin in parent link frame -->
    <origin rpy="-2.967060 -1.570796 0.000000" xyz="0.000971571 -0.0433963 0.093583545"/>
    <parent link="base_link_hithand"/>
    <child link="Right_Little_Basecover"/>
    <axis xyz="0 0 1"/>
    <limit effort="15" lower="-0.261799" upper="0.261799" velocity="3.14"/>
    <dynamics damping="0.5" friction="0"/>
  </joint>
  <link name="Right_Little_Basecover">
    <inertial>
      <origin rpy="0 0 0" xyz="0.02749 0 0"/>
      <mass value="0.0176"/>
      <inertia ixx="1.3450e-6" ixy="0.0" ixz="-1.8183e-7" iyy="1.9874e-6" iyz="0.0" izz="1.0419e-6"/>
    </inertial>
    <visual>
      <origin rpy="0 0 0" xyz="0 0 0"/>
      <geometry>
        <mesh filename="meshes/visual/finger/hit-hand-2-finger-basecover.dae"/>
      </geometry>
      <material name="white"/>
    </visual>
    <collision>
      <origin rpy="0 0 0" xyz="0 0 0"/>
      <geometry name="hithand_Little_base_cover">
        <cylinder length="0.001" radius="0.001"/>
      </geometry>
    </collision>
  </link>
  <!-- +++++ Finger joint 1, Link: Phalanx proximalis ++++++ -->
  <joint name="Right_Little_1" type="revolute">
    <origin rpy="1.5708 0 0" xyz="0 0 0 "/>
    <parent link="Right_Little_Basecover"/>
    <child link="Right_Little_Phaprox"/>
    <axis xyz="0 0 1"/>
    <limit effort="1.15" lower="0.0" upper="1.48353" velocity="3.14"/>
    <!-- Effort limit based on max fingertip force of 10N. Finger tip is approx 11.5cm away from this joint.-->
    <dynamics damping="0.5" friction="0"/>
  </joint>
  <link name="Right_Little_Phaprox">
    <inertial>
      <origin rpy="0 0 0" xyz="0.03076 0.00297 0"/>
      <mass value="0.0232"/>
      <inertia ixx="2.5326e-6" ixy="-9.2551e-7" ixz="-4.0954e-8" iyy="6.9625e-6" iyz="-9.38e-9" izz="7.9108e-6"/>
    </inertial>
    <visual>
      <origin rpy="0 0 0" xyz="0 0 0"/>
      <geometry>
        <mesh filename="meshes/visual/finger/hit-hand-2-finger-phaprox.dae"/>
      </geometry>
      <material name="lightblue"/>
    </visual>
    <collision>
      <origin rpy="0 0 0" xyz="0 0 0"/>
      <geometry>
        <mesh filename="meshes/collision/finger/hit-hand-2-finger-phaprox.dae"/>
      </geometry>
    </collision>
  </link>
  <!-- +++++ Finger joint 2 Phalanx medialis ++++++ -->
  <joint name="Right_Little_2" type="revolute">
    <origin rpy="0 0 0" xyz="0.055 0 0"/>
    <parent link="Right_Little_Phaprox"/>
    <child link="Right_Little_Phamed"/>
    <axis xyz="0 0 1"/>
    <limit effort="0.6" lower="0.0" upper="1.13446" velocity="3.14"/>
    <!-- Effort limit based on max fingertip force of 10N. Finger tip is approx 6cm away from this joint.-->
    <dynamics damping="0.5" friction="0"/>
  </joint>
  <link name="Right_Little_Phamed">
    <inertial>
      <origin rpy="0 0 0" xyz="0.0097 -0.00036 0"/>
      <mass value="0.0158"/>
      <inertia ixx="1.1852e-6" ixy="-2.8845e-8" ixz="-6.1323e-9" iyy="2.4460e-6" iyz="2.4541e-9" izz="2.6537e-6"/>
    </inertial>
    <visual>
      <origin rpy="0 0 0" xyz="0 0 0"/>
      <geometry>
        <mesh filename="meshes/visual/finger/hit-hand-2-finger-phamed.dae"/>
      </geometry>
      <material name="white"/>
    </visual>
    <collision>
      <origin rpy="0 0 0" xyz="0 0 0"/>
      <geometry>
        <mesh filename="meshes/collision/finger/hit-hand-2-finger-phamed.dae"/>
      </geometry>
    </collision>
  </link>
  <!-- +++++ Finger joint 3 Phalanx distalis ++++++ -->
  <joint name="Right_Little_3" type="revolute">
    <origin rpy="0 0 -1.570796" xyz="0.025 0 0"/>
    <parent link="Right_Little_Phamed"/>
    <child link="Right_Little_Phadist"/>
    <axis xyz="0 0 1"/>
    <limit effort="0.35" lower="0.0" upper="1.13446" velocity="3.14"/>
    <!-- Effort limit based on max fingertip force of 10N. Finger tip is approx 3.5cm away from this joint.-->
    <dynamics damping="0.5" friction="0"/>
  </joint>
  <link name="Right_Little_Phadist">
    <inertial>
      <origin rpy="0 0 0" xyz="0.00072 0.00717 0.0"/>
      <mass value="0.0137"/>
      <inertia ixx="1.5519e-6" ixy="-2.037e-9" ixz="0.0" iyy="8.2972e-7" iyz="3.77e-9" izz="1.5788e-6"/>
    </inertial>
    <visual>
      <origin rpy="0 0 0" xyz="0 0 0"/>
      <geometry>
        <mesh filename="meshes/visual/finger/hit-hand-2-finger-phadist.dae"/>
      </geometry>
      <material name="lightblue"/>
    </visual>
    <collision>
      <origin rpy="0 0 0" xyz="0 0 0"/>
      <geometry>
        <mesh filename="meshes/collision/finger/hit-hand-2-finger-phadist.dae"/>
      </geometry>
    </collision>
  </link>
</robot>
